[2023-10-31T00:06:28.185+0000] {taskinstance.py:1159} INFO - Dependencies all met for dep_context=non-requeueable deps ti=<TaskInstance: simple.pokelist scheduled__2023-10-30T00:00:00+00:00 [queued]>
[2023-10-31T00:06:28.193+0000] {taskinstance.py:1159} INFO - Dependencies all met for dep_context=requeueable deps ti=<TaskInstance: simple.pokelist scheduled__2023-10-30T00:00:00+00:00 [queued]>
[2023-10-31T00:06:28.194+0000] {taskinstance.py:1361} INFO - Starting attempt 2 of 2
[2023-10-31T00:06:28.210+0000] {taskinstance.py:1382} INFO - Executing <Task(BashOperator): pokelist> on 2023-10-30 00:00:00+00:00
[2023-10-31T00:06:28.218+0000] {standard_task_runner.py:57} INFO - Started process 201286 to run task
[2023-10-31T00:06:28.222+0000] {standard_task_runner.py:84} INFO - Running: ['***', 'tasks', 'run', 'simple', 'pokelist', 'scheduled__2023-10-30T00:00:00+00:00', '--job-id', '127', '--raw', '--subdir', 'DAGS_FOLDER/pokelist.py', '--cfg-path', '/tmp/tmp0vrl3m6s']
[2023-10-31T00:06:28.227+0000] {standard_task_runner.py:85} INFO - Job 127: Subtask pokelist
[2023-10-31T00:06:28.287+0000] {task_command.py:416} INFO - Running <TaskInstance: simple.pokelist scheduled__2023-10-30T00:00:00+00:00 [running]> on host 015718ee105c
[2023-10-31T00:06:28.374+0000] {taskinstance.py:1662} INFO - Exporting env vars: AIRFLOW_CTX_DAG_EMAIL='***@***.com' AIRFLOW_CTX_DAG_OWNER='***' AIRFLOW_CTX_DAG_ID='simple' AIRFLOW_CTX_TASK_ID='pokelist' AIRFLOW_CTX_EXECUTION_DATE='2023-10-30T00:00:00+00:00' AIRFLOW_CTX_TRY_NUMBER='2' AIRFLOW_CTX_DAG_RUN_ID='scheduled__2023-10-30T00:00:00+00:00'
[2023-10-31T00:06:28.377+0000] {subprocess.py:63} INFO - Tmp dir root location: /tmp
[2023-10-31T00:06:28.378+0000] {subprocess.py:75} INFO - Running command: ['/bin/bash', '-c', 'python3 /opt/***/scripts/pokelist.py']
[2023-10-31T00:06:28.396+0000] {subprocess.py:86} INFO - Output:
[2023-10-31T00:06:29.238+0000] {subprocess.py:93} INFO - /home/***/.local/lib/python3.9/site-packages/pyspark/bin/load-spark-env.sh: line 68: ps: command not found
[2023-10-31T00:06:31.286+0000] {subprocess.py:93} INFO - Setting default log level to "WARN".
[2023-10-31T00:06:31.286+0000] {subprocess.py:93} INFO - To adjust logging level use sc.setLogLevel(newLevel). For SparkR, use setLogLevel(newLevel).
[2023-10-31T00:06:31.521+0000] {subprocess.py:93} INFO - 23/10/31 00:06:31 WARN NativeCodeLoader: Unable to load native-hadoop library for your platform... using builtin-java classes where applicable
[2023-10-31T00:07:30.440+0000] {subprocess.py:93} INFO - A Requisição de nº 1 coletou 50 Pokemons
[2023-10-31T00:07:30.441+0000] {subprocess.py:93} INFO - A Requisição de nº 2 coletou 50 Pokemons
[2023-10-31T00:07:30.442+0000] {subprocess.py:93} INFO - A Requisição de nº 3 coletou 50 Pokemons
[2023-10-31T00:07:30.442+0000] {subprocess.py:93} INFO - A Requisição de nº 4 coletou 50 Pokemons
[2023-10-31T00:07:30.443+0000] {subprocess.py:93} INFO - A Requisição de nº 5 coletou 50 Pokemons
[2023-10-31T00:07:30.443+0000] {subprocess.py:93} INFO - A Requisição de nº 6 coletou 50 Pokemons
[2023-10-31T00:07:30.443+0000] {subprocess.py:93} INFO - A Requisição de nº 7 coletou 50 Pokemons
[2023-10-31T00:07:30.444+0000] {subprocess.py:93} INFO - A Requisição de nº 8 coletou 50 Pokemons
[2023-10-31T00:07:30.444+0000] {subprocess.py:93} INFO - A Requisição de nº 9 coletou 50 Pokemons
[2023-10-31T00:07:30.444+0000] {subprocess.py:93} INFO - A Requisição de nº 10 coletou 50 Pokemons
[2023-10-31T00:07:30.445+0000] {subprocess.py:93} INFO - A Requisição de nº 11 coletou 50 Pokemons
[2023-10-31T00:07:30.445+0000] {subprocess.py:93} INFO - A Requisição de nº 12 coletou 50 Pokemons
[2023-10-31T00:07:30.445+0000] {subprocess.py:93} INFO - A Requisição de nº 13 coletou 50 Pokemons
[2023-10-31T00:07:30.445+0000] {subprocess.py:93} INFO - A Requisição de nº 14 coletou 50 Pokemons
[2023-10-31T00:07:30.446+0000] {subprocess.py:93} INFO - A Requisição de nº 15 coletou 50 Pokemons
[2023-10-31T00:07:30.446+0000] {subprocess.py:93} INFO - A Requisição de nº 16 coletou 50 Pokemons
[2023-10-31T00:07:30.446+0000] {subprocess.py:93} INFO - A Requisição de nº 17 coletou 50 Pokemons
[2023-10-31T00:07:30.446+0000] {subprocess.py:93} INFO - A Requisição de nº 18 coletou 50 Pokemons
[2023-10-31T00:07:30.446+0000] {subprocess.py:93} INFO - A Requisição de nº 19 coletou 50 Pokemons
[2023-10-31T00:07:30.447+0000] {subprocess.py:93} INFO - A Requisição de nº 20 coletou 50 Pokemons
[2023-10-31T00:07:30.447+0000] {subprocess.py:93} INFO - A Requisição de nº 21 coletou 50 Pokemons
[2023-10-31T00:07:30.447+0000] {subprocess.py:93} INFO - A Requisição de nº 22 coletou 50 Pokemons
[2023-10-31T00:07:30.447+0000] {subprocess.py:93} INFO - A Requisição de nº 23 coletou 50 Pokemons
[2023-10-31T00:07:30.447+0000] {subprocess.py:93} INFO - Traceback (most recent call last):
[2023-10-31T00:07:30.448+0000] {subprocess.py:93} INFO -   File "/home/***/.local/lib/python3.9/site-packages/urllib3/connection.py", line 174, in _new_conn
[2023-10-31T00:07:30.448+0000] {subprocess.py:93} INFO -     conn = connection.create_connection(
[2023-10-31T00:07:30.448+0000] {subprocess.py:93} INFO -   File "/home/***/.local/lib/python3.9/site-packages/urllib3/util/connection.py", line 72, in create_connection
[2023-10-31T00:07:30.449+0000] {subprocess.py:93} INFO -     for res in socket.getaddrinfo(host, port, family, socket.SOCK_STREAM):
[2023-10-31T00:07:30.449+0000] {subprocess.py:93} INFO -   File "/usr/local/lib/python3.9/socket.py", line 954, in getaddrinfo
[2023-10-31T00:07:30.449+0000] {subprocess.py:93} INFO -     for res in _socket.getaddrinfo(host, port, family, type, proto, flags):
[2023-10-31T00:07:30.449+0000] {subprocess.py:93} INFO - socket.gaierror: [Errno -3] Temporary failure in name resolution
[2023-10-31T00:07:30.450+0000] {subprocess.py:93} INFO - 
[2023-10-31T00:07:30.450+0000] {subprocess.py:93} INFO - During handling of the above exception, another exception occurred:
[2023-10-31T00:07:30.450+0000] {subprocess.py:93} INFO - 
[2023-10-31T00:07:30.452+0000] {subprocess.py:93} INFO - Traceback (most recent call last):
[2023-10-31T00:07:30.452+0000] {subprocess.py:93} INFO -   File "/home/***/.local/lib/python3.9/site-packages/urllib3/connectionpool.py", line 714, in urlopen
[2023-10-31T00:07:30.453+0000] {subprocess.py:93} INFO -     httplib_response = self._make_request(
[2023-10-31T00:07:30.453+0000] {subprocess.py:93} INFO -   File "/home/***/.local/lib/python3.9/site-packages/urllib3/connectionpool.py", line 403, in _make_request
[2023-10-31T00:07:30.453+0000] {subprocess.py:93} INFO -     self._validate_conn(conn)
[2023-10-31T00:07:30.453+0000] {subprocess.py:93} INFO -   File "/home/***/.local/lib/python3.9/site-packages/urllib3/connectionpool.py", line 1053, in _validate_conn
[2023-10-31T00:07:30.454+0000] {subprocess.py:93} INFO -     conn.connect()
[2023-10-31T00:07:30.454+0000] {subprocess.py:93} INFO -   File "/home/***/.local/lib/python3.9/site-packages/urllib3/connection.py", line 363, in connect
[2023-10-31T00:07:30.454+0000] {subprocess.py:93} INFO -     self.sock = conn = self._new_conn()
[2023-10-31T00:07:30.454+0000] {subprocess.py:93} INFO -   File "/home/***/.local/lib/python3.9/site-packages/urllib3/connection.py", line 186, in _new_conn
[2023-10-31T00:07:30.454+0000] {subprocess.py:93} INFO -     raise NewConnectionError(
[2023-10-31T00:07:30.455+0000] {subprocess.py:93} INFO - urllib3.exceptions.NewConnectionError: <urllib3.connection.HTTPSConnection object at 0x7fee981d08b0>: Failed to establish a new connection: [Errno -3] Temporary failure in name resolution
[2023-10-31T00:07:30.455+0000] {subprocess.py:93} INFO - 
[2023-10-31T00:07:30.455+0000] {subprocess.py:93} INFO - During handling of the above exception, another exception occurred:
[2023-10-31T00:07:30.455+0000] {subprocess.py:93} INFO - 
[2023-10-31T00:07:30.456+0000] {subprocess.py:93} INFO - Traceback (most recent call last):
[2023-10-31T00:07:30.456+0000] {subprocess.py:93} INFO -   File "/home/***/.local/lib/python3.9/site-packages/requests/adapters.py", line 486, in send
[2023-10-31T00:07:30.456+0000] {subprocess.py:93} INFO -     resp = conn.urlopen(
[2023-10-31T00:07:30.457+0000] {subprocess.py:93} INFO -   File "/home/***/.local/lib/python3.9/site-packages/urllib3/connectionpool.py", line 798, in urlopen
[2023-10-31T00:07:30.457+0000] {subprocess.py:93} INFO -     retries = retries.increment(
[2023-10-31T00:07:30.457+0000] {subprocess.py:93} INFO -   File "/home/***/.local/lib/python3.9/site-packages/urllib3/util/retry.py", line 592, in increment
[2023-10-31T00:07:30.457+0000] {subprocess.py:93} INFO -     raise MaxRetryError(_pool, url, error or ResponseError(cause))
[2023-10-31T00:07:30.457+0000] {subprocess.py:93} INFO - urllib3.exceptions.MaxRetryError: HTTPSConnectionPool(host='pokeapi.co', port=443): Max retries exceeded with url: /api/v2/pokemon/?offset=1150&limit=50 (Caused by NewConnectionError('<urllib3.connection.HTTPSConnection object at 0x7fee981d08b0>: Failed to establish a new connection: [Errno -3] Temporary failure in name resolution'))
[2023-10-31T00:07:30.457+0000] {subprocess.py:93} INFO - 
[2023-10-31T00:07:30.457+0000] {subprocess.py:93} INFO - During handling of the above exception, another exception occurred:
[2023-10-31T00:07:30.457+0000] {subprocess.py:93} INFO - 
[2023-10-31T00:07:30.457+0000] {subprocess.py:93} INFO - Traceback (most recent call last):
[2023-10-31T00:07:30.458+0000] {subprocess.py:93} INFO -   File "/opt/***/scripts/pokelist.py", line 29, in <module>
[2023-10-31T00:07:30.458+0000] {subprocess.py:93} INFO -     response = requests.get(url)
[2023-10-31T00:07:30.458+0000] {subprocess.py:93} INFO -   File "/home/***/.local/lib/python3.9/site-packages/requests/api.py", line 73, in get
[2023-10-31T00:07:30.458+0000] {subprocess.py:93} INFO -     return request("get", url, params=params, **kwargs)
[2023-10-31T00:07:30.458+0000] {subprocess.py:93} INFO -   File "/home/***/.local/lib/python3.9/site-packages/requests/api.py", line 59, in request
[2023-10-31T00:07:30.458+0000] {subprocess.py:93} INFO -     return session.request(method=method, url=url, **kwargs)
[2023-10-31T00:07:30.458+0000] {subprocess.py:93} INFO -   File "/home/***/.local/lib/python3.9/site-packages/requests/sessions.py", line 589, in request
[2023-10-31T00:07:30.458+0000] {subprocess.py:93} INFO -     resp = self.send(prep, **send_kwargs)
[2023-10-31T00:07:30.459+0000] {subprocess.py:93} INFO -   File "/home/***/.local/lib/python3.9/site-packages/requests/sessions.py", line 703, in send
[2023-10-31T00:07:30.459+0000] {subprocess.py:93} INFO -     r = adapter.send(request, **kwargs)
[2023-10-31T00:07:30.459+0000] {subprocess.py:93} INFO -   File "/home/***/.local/lib/python3.9/site-packages/requests/adapters.py", line 519, in send
[2023-10-31T00:07:30.459+0000] {subprocess.py:93} INFO -     raise ConnectionError(e, request=request)
[2023-10-31T00:07:30.459+0000] {subprocess.py:93} INFO - requests.exceptions.ConnectionError: HTTPSConnectionPool(host='pokeapi.co', port=443): Max retries exceeded with url: /api/v2/pokemon/?offset=1150&limit=50 (Caused by NewConnectionError('<urllib3.connection.HTTPSConnection object at 0x7fee981d08b0>: Failed to establish a new connection: [Errno -3] Temporary failure in name resolution'))
[2023-10-31T00:07:31.003+0000] {subprocess.py:97} INFO - Command exited with return code 1
[2023-10-31T00:07:31.032+0000] {taskinstance.py:1937} ERROR - Task failed with exception
Traceback (most recent call last):
  File "/home/airflow/.local/lib/python3.9/site-packages/airflow/operators/bash.py", line 210, in execute
    raise AirflowException(
airflow.exceptions.AirflowException: Bash command failed. The command returned a non-zero exit code 1.
[2023-10-31T00:07:31.037+0000] {taskinstance.py:1400} INFO - Marking task as FAILED. dag_id=simple, task_id=pokelist, execution_date=20231030T000000, start_date=20231031T000628, end_date=20231031T000731
[2023-10-31T00:07:31.053+0000] {standard_task_runner.py:104} ERROR - Failed to execute job 127 for task pokelist (Bash command failed. The command returned a non-zero exit code 1.; 201286)
[2023-10-31T00:07:31.077+0000] {local_task_job_runner.py:228} INFO - Task exited with return code 1
[2023-10-31T00:07:31.101+0000] {taskinstance.py:2778} INFO - 0 downstream tasks scheduled from follow-on schedule check
