[2023-10-20T14:55:33.129+0000] {taskinstance.py:1159} INFO - Dependencies all met for dep_context=non-requeueable deps ti=<TaskInstance: simple.pokelist manual__2023-10-20T14:47:06.181221+00:00 [queued]>
[2023-10-20T14:55:33.365+0000] {taskinstance.py:1159} INFO - Dependencies all met for dep_context=requeueable deps ti=<TaskInstance: simple.pokelist manual__2023-10-20T14:47:06.181221+00:00 [queued]>
[2023-10-20T14:55:33.366+0000] {taskinstance.py:1361} INFO - Starting attempt 2 of 2
[2023-10-20T14:55:33.708+0000] {taskinstance.py:1382} INFO - Executing <Task(BashOperator): pokelist> on 2023-10-20 14:47:06.181221+00:00
[2023-10-20T14:55:33.983+0000] {standard_task_runner.py:57} INFO - Started process 6519 to run task
[2023-10-20T14:55:34.029+0000] {standard_task_runner.py:84} INFO - Running: ['***', 'tasks', 'run', 'simple', 'pokelist', 'manual__2023-10-20T14:47:06.181221+00:00', '--job-id', '95', '--raw', '--subdir', 'DAGS_FOLDER/pokelist.py', '--cfg-path', '/tmp/tmph6cgbo0c']
[2023-10-20T14:55:34.088+0000] {standard_task_runner.py:85} INFO - Job 95: Subtask pokelist
[2023-10-20T14:55:34.889+0000] {task_command.py:416} INFO - Running <TaskInstance: simple.pokelist manual__2023-10-20T14:47:06.181221+00:00 [running]> on host 4662b0d5ca37
[2023-10-20T14:55:35.920+0000] {taskinstance.py:1662} INFO - Exporting env vars: AIRFLOW_CTX_DAG_EMAIL='***@***.com' AIRFLOW_CTX_DAG_OWNER='***' AIRFLOW_CTX_DAG_ID='simple' AIRFLOW_CTX_TASK_ID='pokelist' AIRFLOW_CTX_EXECUTION_DATE='2023-10-20T14:47:06.181221+00:00' AIRFLOW_CTX_TRY_NUMBER='2' AIRFLOW_CTX_DAG_RUN_ID='manual__2023-10-20T14:47:06.181221+00:00'
[2023-10-20T14:55:36.040+0000] {subprocess.py:63} INFO - Tmp dir root location: /tmp
[2023-10-20T14:55:36.041+0000] {subprocess.py:75} INFO - Running command: ['/bin/bash', '-c', 'python3 /opt/***/scripts/pokelist.py']
[2023-10-20T14:55:36.405+0000] {subprocess.py:86} INFO - Output:
[2023-10-20T14:56:55.113+0000] {subprocess.py:93} INFO - /home/***/.local/lib/python3.9/site-packages/pyspark/bin/load-spark-env.sh: line 68: ps: command not found
[2023-10-20T14:57:45.509+0000] {subprocess.py:93} INFO - Setting default log level to "WARN".
[2023-10-20T14:57:45.511+0000] {subprocess.py:93} INFO - To adjust logging level use sc.setLogLevel(newLevel). For SparkR, use setLogLevel(newLevel).
[2023-10-20T14:57:46.599+0000] {subprocess.py:93} INFO - 23/10/20 14:57:46 WARN NativeCodeLoader: Unable to load native-hadoop library for your platform... using builtin-java classes where applicable
[2023-10-20T14:57:52.142+0000] {subprocess.py:93} INFO - 23/10/20 14:57:52 WARN Utils: Service 'SparkUI' could not bind on port 4040. Attempting port 4041.
[2023-10-20T14:57:52.143+0000] {subprocess.py:93} INFO - 23/10/20 14:57:52 WARN Utils: Service 'SparkUI' could not bind on port 4041. Attempting port 4042.
[2023-10-20T14:57:52.143+0000] {subprocess.py:93} INFO - 23/10/20 14:57:52 WARN Utils: Service 'SparkUI' could not bind on port 4042. Attempting port 4043.
[2023-10-20T14:57:52.144+0000] {subprocess.py:93} INFO - 23/10/20 14:57:52 WARN Utils: Service 'SparkUI' could not bind on port 4043. Attempting port 4044.
[2023-10-20T14:57:52.144+0000] {subprocess.py:93} INFO - 23/10/20 14:57:52 WARN Utils: Service 'SparkUI' could not bind on port 4044. Attempting port 4045.
[2023-10-20T14:57:52.144+0000] {subprocess.py:93} INFO - 23/10/20 14:57:52 WARN Utils: Service 'SparkUI' could not bind on port 4045. Attempting port 4046.
[2023-10-20T14:57:52.145+0000] {subprocess.py:93} INFO - 23/10/20 14:57:52 WARN Utils: Service 'SparkUI' could not bind on port 4046. Attempting port 4047.
[2023-10-20T14:57:52.145+0000] {subprocess.py:93} INFO - 23/10/20 14:57:52 WARN Utils: Service 'SparkUI' could not bind on port 4047. Attempting port 4048.
[2023-10-20T14:57:52.184+0000] {subprocess.py:93} INFO - 23/10/20 14:57:52 WARN Utils: Service 'SparkUI' could not bind on port 4048. Attempting port 4049.
[2023-10-20T14:58:12.273+0000] {subprocess.py:93} INFO - A Requisição de nº 1 coletou 50 Pokemons
[2023-10-20T14:58:12.295+0000] {subprocess.py:93} INFO - A Requisição de nº 2 coletou 50 Pokemons
[2023-10-20T14:58:12.295+0000] {subprocess.py:93} INFO - A Requisição de nº 3 coletou 50 Pokemons
[2023-10-20T14:58:12.295+0000] {subprocess.py:93} INFO - A Requisição de nº 4 coletou 50 Pokemons
[2023-10-20T14:58:12.296+0000] {subprocess.py:93} INFO - Traceback (most recent call last):
[2023-10-20T14:58:12.296+0000] {subprocess.py:93} INFO -   File "/home/***/.local/lib/python3.9/site-packages/urllib3/connection.py", line 174, in _new_conn
[2023-10-20T14:58:12.307+0000] {subprocess.py:93} INFO -     conn = connection.create_connection(
[2023-10-20T14:58:12.307+0000] {subprocess.py:93} INFO -   File "/home/***/.local/lib/python3.9/site-packages/urllib3/util/connection.py", line 72, in create_connection
[2023-10-20T14:58:12.307+0000] {subprocess.py:93} INFO -     for res in socket.getaddrinfo(host, port, family, socket.SOCK_STREAM):
[2023-10-20T14:58:12.307+0000] {subprocess.py:93} INFO -   File "/usr/local/lib/python3.9/socket.py", line 954, in getaddrinfo
[2023-10-20T14:58:12.307+0000] {subprocess.py:93} INFO -     for res in _socket.getaddrinfo(host, port, family, type, proto, flags):
[2023-10-20T14:58:12.307+0000] {subprocess.py:93} INFO - socket.gaierror: [Errno -3] Temporary failure in name resolution
[2023-10-20T14:58:12.308+0000] {subprocess.py:93} INFO - 
[2023-10-20T14:58:12.308+0000] {subprocess.py:93} INFO - During handling of the above exception, another exception occurred:
[2023-10-20T14:58:12.308+0000] {subprocess.py:93} INFO - 
[2023-10-20T14:58:12.308+0000] {subprocess.py:93} INFO - Traceback (most recent call last):
[2023-10-20T14:58:12.308+0000] {subprocess.py:93} INFO -   File "/home/***/.local/lib/python3.9/site-packages/urllib3/connectionpool.py", line 714, in urlopen
[2023-10-20T14:58:12.308+0000] {subprocess.py:93} INFO -     httplib_response = self._make_request(
[2023-10-20T14:58:12.308+0000] {subprocess.py:93} INFO -   File "/home/***/.local/lib/python3.9/site-packages/urllib3/connectionpool.py", line 403, in _make_request
[2023-10-20T14:58:12.308+0000] {subprocess.py:93} INFO -     self._validate_conn(conn)
[2023-10-20T14:58:12.308+0000] {subprocess.py:93} INFO -   File "/home/***/.local/lib/python3.9/site-packages/urllib3/connectionpool.py", line 1053, in _validate_conn
[2023-10-20T14:58:12.309+0000] {subprocess.py:93} INFO -     conn.connect()
[2023-10-20T14:58:12.309+0000] {subprocess.py:93} INFO -   File "/home/***/.local/lib/python3.9/site-packages/urllib3/connection.py", line 363, in connect
[2023-10-20T14:58:12.310+0000] {subprocess.py:93} INFO -     self.sock = conn = self._new_conn()
[2023-10-20T14:58:12.310+0000] {subprocess.py:93} INFO -   File "/home/***/.local/lib/python3.9/site-packages/urllib3/connection.py", line 186, in _new_conn
[2023-10-20T14:58:12.310+0000] {subprocess.py:93} INFO -     raise NewConnectionError(
[2023-10-20T14:58:12.310+0000] {subprocess.py:93} INFO - urllib3.exceptions.NewConnectionError: <urllib3.connection.HTTPSConnection object at 0x7fbafdf094f0>: Failed to establish a new connection: [Errno -3] Temporary failure in name resolution
[2023-10-20T14:58:12.388+0000] {subprocess.py:93} INFO - 
[2023-10-20T14:58:12.388+0000] {subprocess.py:93} INFO - During handling of the above exception, another exception occurred:
[2023-10-20T14:58:12.388+0000] {subprocess.py:93} INFO - 
[2023-10-20T14:58:12.388+0000] {subprocess.py:93} INFO - Traceback (most recent call last):
[2023-10-20T14:58:12.389+0000] {subprocess.py:93} INFO -   File "/home/***/.local/lib/python3.9/site-packages/requests/adapters.py", line 486, in send
[2023-10-20T14:58:12.389+0000] {subprocess.py:93} INFO -     resp = conn.urlopen(
[2023-10-20T14:58:12.389+0000] {subprocess.py:93} INFO -   File "/home/***/.local/lib/python3.9/site-packages/urllib3/connectionpool.py", line 798, in urlopen
[2023-10-20T14:58:12.389+0000] {subprocess.py:93} INFO -     retries = retries.increment(
[2023-10-20T14:58:12.389+0000] {subprocess.py:93} INFO -   File "/home/***/.local/lib/python3.9/site-packages/urllib3/util/retry.py", line 592, in increment
[2023-10-20T14:58:12.389+0000] {subprocess.py:93} INFO -     raise MaxRetryError(_pool, url, error or ResponseError(cause))
[2023-10-20T14:58:12.389+0000] {subprocess.py:93} INFO - urllib3.exceptions.MaxRetryError: HTTPSConnectionPool(host='pokeapi.co', port=443): Max retries exceeded with url: /api/v2/pokemon/?offset=200&limit=50 (Caused by NewConnectionError('<urllib3.connection.HTTPSConnection object at 0x7fbafdf094f0>: Failed to establish a new connection: [Errno -3] Temporary failure in name resolution'))
[2023-10-20T14:58:12.390+0000] {subprocess.py:93} INFO - 
[2023-10-20T14:58:12.390+0000] {subprocess.py:93} INFO - During handling of the above exception, another exception occurred:
[2023-10-20T14:58:12.390+0000] {subprocess.py:93} INFO - 
[2023-10-20T14:58:12.390+0000] {subprocess.py:93} INFO - Traceback (most recent call last):
[2023-10-20T14:58:12.390+0000] {subprocess.py:93} INFO -   File "/opt/***/scripts/pokelist.py", line 29, in <module>
[2023-10-20T14:58:12.390+0000] {subprocess.py:93} INFO -     response = requests.get(url)
[2023-10-20T14:58:12.390+0000] {subprocess.py:93} INFO -   File "/home/***/.local/lib/python3.9/site-packages/requests/api.py", line 73, in get
[2023-10-20T14:58:12.390+0000] {subprocess.py:93} INFO -     return request("get", url, params=params, **kwargs)
[2023-10-20T14:58:12.390+0000] {subprocess.py:93} INFO -   File "/home/***/.local/lib/python3.9/site-packages/requests/api.py", line 59, in request
[2023-10-20T14:58:12.505+0000] {subprocess.py:93} INFO -     return session.request(method=method, url=url, **kwargs)
[2023-10-20T14:58:12.505+0000] {subprocess.py:93} INFO -   File "/home/***/.local/lib/python3.9/site-packages/requests/sessions.py", line 589, in request
[2023-10-20T14:58:12.506+0000] {subprocess.py:93} INFO -     resp = self.send(prep, **send_kwargs)
[2023-10-20T14:58:12.506+0000] {subprocess.py:93} INFO -   File "/home/***/.local/lib/python3.9/site-packages/requests/sessions.py", line 703, in send
[2023-10-20T14:58:12.506+0000] {subprocess.py:93} INFO -     r = adapter.send(request, **kwargs)
[2023-10-20T14:58:12.506+0000] {subprocess.py:93} INFO -   File "/home/***/.local/lib/python3.9/site-packages/requests/adapters.py", line 519, in send
[2023-10-20T14:58:12.506+0000] {subprocess.py:93} INFO -     raise ConnectionError(e, request=request)
[2023-10-20T14:58:12.506+0000] {subprocess.py:93} INFO - requests.exceptions.ConnectionError: HTTPSConnectionPool(host='pokeapi.co', port=443): Max retries exceeded with url: /api/v2/pokemon/?offset=200&limit=50 (Caused by NewConnectionError('<urllib3.connection.HTTPSConnection object at 0x7fbafdf094f0>: Failed to establish a new connection: [Errno -3] Temporary failure in name resolution'))
[2023-10-20T14:58:15.433+0000] {subprocess.py:97} INFO - Command exited with return code 1
[2023-10-20T14:58:15.465+0000] {taskinstance.py:1937} ERROR - Task failed with exception
Traceback (most recent call last):
  File "/home/airflow/.local/lib/python3.9/site-packages/airflow/operators/bash.py", line 210, in execute
    raise AirflowException(
airflow.exceptions.AirflowException: Bash command failed. The command returned a non-zero exit code 1.
[2023-10-20T14:58:15.501+0000] {taskinstance.py:1400} INFO - Marking task as FAILED. dag_id=simple, task_id=pokelist, execution_date=20231020T144706, start_date=20231020T145533, end_date=20231020T145815
[2023-10-20T14:58:15.632+0000] {standard_task_runner.py:104} ERROR - Failed to execute job 95 for task pokelist (Bash command failed. The command returned a non-zero exit code 1.; 6519)
[2023-10-20T14:58:15.703+0000] {local_task_job_runner.py:228} INFO - Task exited with return code 1
[2023-10-20T14:58:15.753+0000] {taskinstance.py:2778} INFO - 0 downstream tasks scheduled from follow-on schedule check
