[2023-10-20T14:54:18.333+0000] {taskinstance.py:1159} INFO - Dependencies all met for dep_context=non-requeueable deps ti=<TaskInstance: simple.pokelist manual__2023-10-20T14:46:34.716597+00:00 [queued]>
[2023-10-20T14:54:18.353+0000] {taskinstance.py:1159} INFO - Dependencies all met for dep_context=requeueable deps ti=<TaskInstance: simple.pokelist manual__2023-10-20T14:46:34.716597+00:00 [queued]>
[2023-10-20T14:54:18.353+0000] {taskinstance.py:1361} INFO - Starting attempt 2 of 2
[2023-10-20T14:54:18.389+0000] {taskinstance.py:1382} INFO - Executing <Task(BashOperator): pokelist> on 2023-10-20 14:46:34.716597+00:00
[2023-10-20T14:54:18.403+0000] {standard_task_runner.py:57} INFO - Started process 6187 to run task
[2023-10-20T14:54:18.425+0000] {standard_task_runner.py:84} INFO - Running: ['***', 'tasks', 'run', 'simple', 'pokelist', 'manual__2023-10-20T14:46:34.716597+00:00', '--job-id', '88', '--raw', '--subdir', 'DAGS_FOLDER/pokelist.py', '--cfg-path', '/tmp/tmplggs77lf']
[2023-10-20T14:54:18.450+0000] {standard_task_runner.py:85} INFO - Job 88: Subtask pokelist
[2023-10-20T14:54:18.596+0000] {task_command.py:416} INFO - Running <TaskInstance: simple.pokelist manual__2023-10-20T14:46:34.716597+00:00 [running]> on host 4662b0d5ca37
[2023-10-20T14:54:18.919+0000] {taskinstance.py:1662} INFO - Exporting env vars: AIRFLOW_CTX_DAG_EMAIL='***@***.com' AIRFLOW_CTX_DAG_OWNER='***' AIRFLOW_CTX_DAG_ID='simple' AIRFLOW_CTX_TASK_ID='pokelist' AIRFLOW_CTX_EXECUTION_DATE='2023-10-20T14:46:34.716597+00:00' AIRFLOW_CTX_TRY_NUMBER='2' AIRFLOW_CTX_DAG_RUN_ID='manual__2023-10-20T14:46:34.716597+00:00'
[2023-10-20T14:54:18.922+0000] {subprocess.py:63} INFO - Tmp dir root location: /tmp
[2023-10-20T14:54:18.932+0000] {subprocess.py:75} INFO - Running command: ['/bin/bash', '-c', 'python3 /opt/***/scripts/pokelist.py']
[2023-10-20T14:54:18.984+0000] {subprocess.py:86} INFO - Output:
[2023-10-20T14:54:23.708+0000] {subprocess.py:93} INFO - /home/***/.local/lib/python3.9/site-packages/pyspark/bin/load-spark-env.sh: line 68: ps: command not found
[2023-10-20T14:54:57.801+0000] {subprocess.py:93} INFO - Setting default log level to "WARN".
[2023-10-20T14:54:57.804+0000] {subprocess.py:93} INFO - To adjust logging level use sc.setLogLevel(newLevel). For SparkR, use setLogLevel(newLevel).
[2023-10-20T14:55:01.070+0000] {subprocess.py:93} INFO - 23/10/20 14:55:01 WARN NativeCodeLoader: Unable to load native-hadoop library for your platform... using builtin-java classes where applicable
[2023-10-20T14:56:49.089+0000] {subprocess.py:93} INFO - A Requisição de nº 1 coletou 50 Pokemons
[2023-10-20T14:56:49.137+0000] {subprocess.py:93} INFO - A Requisição de nº 2 coletou 50 Pokemons
[2023-10-20T14:56:49.369+0000] {subprocess.py:93} INFO - A Requisição de nº 3 coletou 50 Pokemons
[2023-10-20T14:56:51.231+0000] {subprocess.py:93} INFO - A Requisição de nº 4 coletou 50 Pokemons
[2023-10-20T14:56:51.266+0000] {subprocess.py:93} INFO - A Requisição de nº 5 coletou 50 Pokemons
[2023-10-20T14:56:51.411+0000] {subprocess.py:93} INFO - A Requisição de nº 6 coletou 50 Pokemons
[2023-10-20T14:56:51.424+0000] {subprocess.py:93} INFO - A Requisição de nº 7 coletou 50 Pokemons
[2023-10-20T14:56:51.430+0000] {subprocess.py:93} INFO - Traceback (most recent call last):
[2023-10-20T14:56:51.432+0000] {subprocess.py:93} INFO -   File "/home/***/.local/lib/python3.9/site-packages/urllib3/connectionpool.py", line 714, in urlopen
[2023-10-20T14:56:51.438+0000] {subprocess.py:93} INFO -     httplib_response = self._make_request(
[2023-10-20T14:56:51.444+0000] {subprocess.py:93} INFO -   File "/home/***/.local/lib/python3.9/site-packages/urllib3/connectionpool.py", line 403, in _make_request
[2023-10-20T14:56:51.448+0000] {subprocess.py:93} INFO -     self._validate_conn(conn)
[2023-10-20T14:56:51.448+0000] {subprocess.py:93} INFO -   File "/home/***/.local/lib/python3.9/site-packages/urllib3/connectionpool.py", line 1053, in _validate_conn
[2023-10-20T14:56:51.448+0000] {subprocess.py:93} INFO -     conn.connect()
[2023-10-20T14:56:51.448+0000] {subprocess.py:93} INFO -   File "/home/***/.local/lib/python3.9/site-packages/urllib3/connection.py", line 419, in connect
[2023-10-20T14:56:51.450+0000] {subprocess.py:93} INFO -     self.sock = ssl_wrap_socket(
[2023-10-20T14:56:51.450+0000] {subprocess.py:93} INFO -   File "/home/***/.local/lib/python3.9/site-packages/urllib3/util/ssl_.py", line 449, in ssl_wrap_socket
[2023-10-20T14:56:51.451+0000] {subprocess.py:93} INFO -     ssl_sock = _ssl_wrap_socket_impl(
[2023-10-20T14:56:51.456+0000] {subprocess.py:93} INFO -   File "/home/***/.local/lib/python3.9/site-packages/urllib3/util/ssl_.py", line 493, in _ssl_wrap_socket_impl
[2023-10-20T14:56:51.460+0000] {subprocess.py:93} INFO -     return ssl_context.wrap_socket(sock, server_hostname=server_hostname)
[2023-10-20T14:56:51.460+0000] {subprocess.py:93} INFO -   File "/usr/local/lib/python3.9/ssl.py", line 501, in wrap_socket
[2023-10-20T14:56:51.818+0000] {subprocess.py:93} INFO -     return self.sslsocket_class._create(
[2023-10-20T14:56:52.432+0000] {subprocess.py:93} INFO -   File "/usr/local/lib/python3.9/ssl.py", line 1074, in _create
[2023-10-20T14:56:52.453+0000] {subprocess.py:93} INFO -     self.do_handshake()
[2023-10-20T14:56:52.479+0000] {subprocess.py:93} INFO -   File "/usr/local/lib/python3.9/ssl.py", line 1343, in do_handshake
[2023-10-20T14:56:53.533+0000] {subprocess.py:93} INFO -     self._sslobj.do_handshake()
[2023-10-20T14:56:53.582+0000] {subprocess.py:93} INFO - ssl.SSLEOFError: EOF occurred in violation of protocol (_ssl.c:1129)
[2023-10-20T14:56:53.643+0000] {subprocess.py:93} INFO - 
[2023-10-20T14:56:54.460+0000] {subprocess.py:93} INFO - During handling of the above exception, another exception occurred:
[2023-10-20T14:56:54.477+0000] {subprocess.py:93} INFO - 
[2023-10-20T14:56:54.477+0000] {subprocess.py:93} INFO - Traceback (most recent call last):
[2023-10-20T14:56:54.477+0000] {subprocess.py:93} INFO -   File "/home/***/.local/lib/python3.9/site-packages/requests/adapters.py", line 486, in send
[2023-10-20T14:56:54.478+0000] {subprocess.py:93} INFO -     resp = conn.urlopen(
[2023-10-20T14:56:54.478+0000] {subprocess.py:93} INFO -   File "/home/***/.local/lib/python3.9/site-packages/urllib3/connectionpool.py", line 798, in urlopen
[2023-10-20T14:56:54.478+0000] {subprocess.py:93} INFO -     retries = retries.increment(
[2023-10-20T14:56:54.478+0000] {subprocess.py:93} INFO -   File "/home/***/.local/lib/python3.9/site-packages/urllib3/util/retry.py", line 592, in increment
[2023-10-20T14:56:54.478+0000] {subprocess.py:93} INFO -     raise MaxRetryError(_pool, url, error or ResponseError(cause))
[2023-10-20T14:56:54.478+0000] {subprocess.py:93} INFO - urllib3.exceptions.MaxRetryError: HTTPSConnectionPool(host='pokeapi.co', port=443): Max retries exceeded with url: /api/v2/pokemon/?offset=350&limit=50 (Caused by SSLError(SSLEOFError(8, 'EOF occurred in violation of protocol (_ssl.c:1129)')))
[2023-10-20T14:56:54.478+0000] {subprocess.py:93} INFO - 
[2023-10-20T14:56:54.479+0000] {subprocess.py:93} INFO - During handling of the above exception, another exception occurred:
[2023-10-20T14:56:54.479+0000] {subprocess.py:93} INFO - 
[2023-10-20T14:56:54.484+0000] {subprocess.py:93} INFO - Traceback (most recent call last):
[2023-10-20T14:56:54.484+0000] {subprocess.py:93} INFO -   File "/opt/***/scripts/pokelist.py", line 29, in <module>
[2023-10-20T14:56:54.484+0000] {subprocess.py:93} INFO -     response = requests.get(url)
[2023-10-20T14:56:54.485+0000] {subprocess.py:93} INFO -   File "/home/***/.local/lib/python3.9/site-packages/requests/api.py", line 73, in get
[2023-10-20T14:56:54.485+0000] {subprocess.py:93} INFO -     return request("get", url, params=params, **kwargs)
[2023-10-20T14:56:54.485+0000] {subprocess.py:93} INFO -   File "/home/***/.local/lib/python3.9/site-packages/requests/api.py", line 59, in request
[2023-10-20T14:56:54.485+0000] {subprocess.py:93} INFO -     return session.request(method=method, url=url, **kwargs)
[2023-10-20T14:56:54.485+0000] {subprocess.py:93} INFO -   File "/home/***/.local/lib/python3.9/site-packages/requests/sessions.py", line 589, in request
[2023-10-20T14:56:54.485+0000] {subprocess.py:93} INFO -     resp = self.send(prep, **send_kwargs)
[2023-10-20T14:56:54.485+0000] {subprocess.py:93} INFO -   File "/home/***/.local/lib/python3.9/site-packages/requests/sessions.py", line 703, in send
[2023-10-20T14:56:54.486+0000] {subprocess.py:93} INFO -     r = adapter.send(request, **kwargs)
[2023-10-20T14:56:54.486+0000] {subprocess.py:93} INFO -   File "/home/***/.local/lib/python3.9/site-packages/requests/adapters.py", line 517, in send
[2023-10-20T14:56:54.486+0000] {subprocess.py:93} INFO -     raise SSLError(e, request=request)
[2023-10-20T14:56:54.486+0000] {subprocess.py:93} INFO - requests.exceptions.SSLError: HTTPSConnectionPool(host='pokeapi.co', port=443): Max retries exceeded with url: /api/v2/pokemon/?offset=350&limit=50 (Caused by SSLError(SSLEOFError(8, 'EOF occurred in violation of protocol (_ssl.c:1129)')))
[2023-10-20T14:57:11.841+0000] {subprocess.py:97} INFO - Command exited with return code 1
[2023-10-20T14:57:11.938+0000] {taskinstance.py:1937} ERROR - Task failed with exception
Traceback (most recent call last):
  File "/home/airflow/.local/lib/python3.9/site-packages/airflow/operators/bash.py", line 210, in execute
    raise AirflowException(
airflow.exceptions.AirflowException: Bash command failed. The command returned a non-zero exit code 1.
[2023-10-20T14:57:12.043+0000] {taskinstance.py:1400} INFO - Marking task as FAILED. dag_id=simple, task_id=pokelist, execution_date=20231020T144634, start_date=20231020T145418, end_date=20231020T145712
[2023-10-20T14:57:12.333+0000] {standard_task_runner.py:104} ERROR - Failed to execute job 88 for task pokelist (Bash command failed. The command returned a non-zero exit code 1.; 6187)
[2023-10-20T14:57:12.619+0000] {local_task_job_runner.py:228} INFO - Task exited with return code 1
[2023-10-20T14:57:12.765+0000] {taskinstance.py:2778} INFO - 0 downstream tasks scheduled from follow-on schedule check
